Workbook

Sheet Pro Forma_BLANK
B2: INPUTS | G2: Year | H2: 0 | I2: 1 | J2: =I2+1 -> 2 | K2: =J2+1 -> 3 | L2: =K2+1 -> 4 | M2: =L2+1 -> 5 | N2: =M2+1 -> 6 | O2: =N2+1 -> 7 | P2: =O2+1 -> 8 | Q2: =P2+1 -> 9 | ... S2: =R2+1 -> 11
B5: Valuation Assumptions: | G5: Pro Forma:
B6: Purchase Price | C6: 38900000
B7: Tax Assessment % | C7: 0.6 | G7: Rental Revenue:
B8: Tax Rate | C8: 0.012775 | G8: Potential Base Rent | I8: =208315*12 -> 2499780 | J8: =SUM(I8*1.03) -> 2574773.4 | K8: =SUM(J8*1.03) -> 2652016.6 | L8: =SUM(K8*1.03) -> 2731577.1 | M8: =SUM(L8*1.03) -> 2813524.4 | N8: =SUM(M8*1.03) -> 2897930.1 | O8: =SUM(N8*1.03) -> 2984868 | P8: =SUM(O8*1.03) -> 3074414.1 | Q8: =SUM(P8*1.03) -> 3166646.5 | R8: =SUM(Q8*1.03) -> 3261645.9
B9: Tax Inflation | C9: 0.03 | G9: Absorp. & Turnover Vacancy
B10: Property Mgmt Fee | C10: 0.025 | D10: of EGR | G10: Scheduled Base Rent | I10: =SUM(I8:I9) -> 2499780 | J10: =SUM(J8:J9) -> 2574773.4 | K10: =SUM(K8:K9) -> 2652016.6 | L10: =SUM(L8:L9) -> 2731577.1 | M10: =SUM(M8:M9) -> 2813524.4 | N10: =SUM(N8:N9) -> 2897930.1 | O10: =SUM(O8:O9) -> 2984868 | P10: =SUM(P8:P9) -> 3074414.1 | ... R10: =SUM(R8:R9) -> 3261645.9
B11: Other Expenses | C11: 199548 | G11: Other Tenant Revenue:
B12: Other Expense Inflation | C12: 0.03 | D12: growth | G12: Total Expense Recoveries | I12: =20941*12 -> 251292 | J12: =SUM(I12*1.03) -> 258830.76 | K12: =SUM(J12*1.03) -> 266595.68 | L12: =SUM(K12*1.03) -> 274593.55 | M12: =SUM(L12*1.03) -> 282831.36 | N12: =SUM(M12*1.03) -> 291316.3 | O12: =SUM(N12*1.03) -> 300055.79 | P12: =SUM(O12*1.03) -> 309057.46 | Q12: =SUM(P12*1.03) -> 318329.19 | R12: =SUM(Q12*1.03) -> 327879.06
B13: CapEx Reserve | C13: 0.2 | D13: /sf | G13: Potential Gross Revenue | I13: =SUM(I10:I12) -> 2751072 | J13: =SUM(J10:J12) -> 2833604.2 | K13: =SUM(K10:K12) -> 2918612.3 | L13: =SUM(L10:L12) -> 3006170.7 | M13: =SUM(M10:M12) -> 3096355.8 | N13: =SUM(N10:N12) -> 3189246.4 | O13: =SUM(O10:O12) -> 3284923.8 | P13: =SUM(P10:P12) -> 3383471.6 | ... R13: =SUM(R10:R12) -> 3589525
B14: CapEx Reserve Inflation | C14: 0.03 | D14: growth | G14: Vacancy & Credit Loss:
G15: Vacancy Allowance
B16: Reversion Assumptions: | G16: Effective Gross Revenue | I16: =SUM(I13, I15) -> 2751072 | J16: =SUM(J13, J15) -> 2833604.2 | K16: =SUM(K13, K15) -> 2918612.3 | L16: =SUM(L13, L15) -> 3006170.7 | M16: =SUM(M13, M15) -> 3096355.8 | N16: =SUM(N13, N15) -> 3189246.4 | O16: =SUM(O13, O15) -> 3284923.8 | P16: =SUM(P13, P15) -> 3383471.6 | ... R16: =SUM(R13, R15) -> 3589525
B17: Net Operating Income (Y11) | C17: =S26 -> 2664733 | G17: Operating Expenses:
B18: Occupancy Gross-up Adj. | C18: 0 | G18: Property taxes | I18: =C8*(C6*C7) -> 298168.5 | J18: =I18*(1+$C$9) -> 307113.55 | K18: =J18*(1+$C$9) -> 316326.96 | L18: =K18*(1+$C$9) -> 325816.77 | M18: =L18*(1+$C$9) -> 335591.27 | N18: =M18*(1+$C$9) -> 345659.01 | O18: =N18*(1+$C$9) -> 356028.78 | P18: =O18*(1+$C$9) -> 366709.65 | Q18: =P18*(1+$C$9) -> 377710.94 | R18: =Q18*(1+$C$9) -> 389042.26
B19: NOI To Capitalize | C19: =SUM(C17:C18) -> 2664733 | G19: Utilities | I19: =8500*12 -> 102000 | J19: =SUM(I19*1.03) -> 105060 | K19: =SUM(J19*1.03) -> 108211.8 | L19: =SUM(K19*1.03) -> 111458.15 | M19: =SUM(L19*1.03) -> 114801.9 | N19: =SUM(M19*1.03) -> 118245.96 | O19: =SUM(N19*1.03) -> 121793.33 | P19: =SUM(O19*1.03) -> 125447.13 | Q19: =SUM(P19*1.03) -> 129210.55 | R19: =SUM(Q19*1.03) -> 133086.86
B20: Exit Cap Rate | C20: 0.0665 | G20: Cleaning | I20: =6000*12 -> 72000 | J20: =SUM(I20*1.03) -> 74160 | K20: =SUM(J20*1.03) -> 76384.8 | L20: =SUM(K20*1.03) -> 78676.344 | M20: =SUM(L20*1.03) -> 81036.634 | N20: =SUM(M20*1.03) -> 83467.733 | O20: =SUM(N20*1.03) -> 85971.765 | P20: =SUM(O20*1.03) -> 88550.918 | Q20: =SUM(P20*1.03) -> 91207.446 | R20: =SUM(Q20*1.03) -> 93943.669
B21: Adjusted Gross Sale Price | C21: =C19/C20 -> 40071173 | G21: Repairs and Maintenance | I21: =2250*12 -> 27000 | J21: =SUM(I21*1.03) -> 27810 | K21: =SUM(J21*1.03) -> 28644.3 | L21: =SUM(K21*1.03) -> 29503.629 | M21: =SUM(L21*1.03) -> 30388.738 | N21: =SUM(M21*1.03) -> 31300.4 | O21: =SUM(N21*1.03) -> 32239.412 | P21: =SUM(O21*1.03) -> 33206.594 | Q21: =SUM(P21*1.03) -> 34202.792 | R21: =SUM(Q21*1.03) -> 35228.876
B22: Selling Costs (1% of price) | C22: =-D22*C21 -> -400711.73 | D22: 0.01 | G22: Short Term Expenses | L22: - | M22: - | N22: - | O22: - | P22: - | Q22: - | R22: -
B23: Net Sales Proceeds | C23: =SUM(C21:C22) -> 39670461 | G23: Property Management | I23: =I16*C10 -> 68776.8 | J23: =J16*$C$10 -> 70840.104 | K23: =K16*$C$10 -> 72965.307 | L23: =L16*$C$10 -> 75154.266 | M23: =M16*$C$10 -> 77408.894 | N23: =N16*$C$10 -> 79731.161 | O23: =O16*$C$10 -> 82123.096 | P23: =P16*$C$10 -> 84586.789 | Q23: =Q16*$C$10 -> 87124.393 | R23: =R16*$C$10 -> 89738.124
G24: Other Expenses | I24: =C11 -> 199548 | J24: =I24*(1+$C$14) -> 205534.44 | K24: =J24*(1+$C$14) -> 211700.47 | L24: =K24*(1+$C$14) -> 218051.49 | M24: =L24*(1+$C$14) -> 224593.03 | N24: =M24*(1+$C$14) -> 231330.82 | O24: =N24*(1+$C$14) -> 238270.75 | P24: =O24*(1+$C$14) -> 245418.87 | Q24: =P24*(1+$C$14) -> 252781.44 | R24: =Q24*(1+$C$14) -> 260364.88
B25: Loan Assumptions: | G25: Total Operating Expenses | I25: =SUM(I18:I24) -> 767493.3 | J25: =SUM(J18:J24) -> 790518.1 | K25: =SUM(K18:K24) -> 814233.64 | L25: =SUM(L18:L24) -> 838660.65 | M25: =SUM(M18:M24) -> 863820.47 | N25: =SUM(N18:N24) -> 889735.08 | O25: =SUM(O18:O24) -> 916427.14 | P25: =SUM(P18:P24) -> 943919.95 | ... R25: =SUM(R18:R24) -> 1001404.7
B26: LTV | C26: 0.59 | G26: Net Operating Income | I26: =SUM(I16-I25) -> 1983578.7 | J26: =SUM(J16-J25) -> 2043086.1 | K26: =SUM(K16-K25) -> 2104378.6 | L26: =SUM(L16-L25) -> 2167510 | M26: =SUM(M16-M25) -> 2232535.3 | N26: =SUM(N16-N25) -> 2299511.4 | O26: =SUM(O16-O25) -> 2368496.7 | P26: =SUM(P16-P25) -> 2439551.6 | ... R26: =SUM(R16-R25) -> 2588120.3 | S26: 2664733
B27: Loan Amount | C27: 23000000 | G27: Leasing Costs:
B28: Interest Rate | C28: 0.0433 | G28: Tenant Improvements | K28: 230640 | P28: 595260
B29: Amortization | C29: 30 | D29: years | G29: Leasing Commissions
B30: Monthly Payment | C30: =PMT(C28/12,C29*12,C27)*-1 -> 114225.96 | G30: Total Leasing Costs | I30: =SUM(I28,I29) -> 0 | J30: =SUM(J28,J29) -> 0 | K30: =SUM(K28,K29) -> 230640 | L30: =SUM(L28,L29) -> 0 | M30: =SUM(M28,M29) -> 0 | N30: =SUM(N28,N29) -> 0 | O30: =SUM(O28,O29) -> 0 | P30: =SUM(P28,P29) -> 595260 | ... R30: =SUM(R28,R29) -> 0
G31: Capital Expenditures:
G32: Capital Reserve | I32: =$C$13*175000 -> 35000 | J32: =I32*(1+$C$14) -> 36050 | K32: =J32*(1+$C$14) -> 37131.5 | L32: =K32*(1+$C$14) -> 38245.445 | M32: =L32*(1+$C$14) -> 39392.808 | N32: =M32*(1+$C$14) -> 40574.593 | O32: =N32*(1+$C$14) -> 41791.83 | P32: =O32*(1+$C$14) -> 43045.585 | Q32: =P32*(1+$C$14) -> 44336.953 | R32: =Q32*(1+$C$14) -> 45667.061
G33: Total Leasing & Capital Costs | I33: =SUM(I30,I32) -> 35000 | J33: =SUM(J30,J32) -> 36050 | K33: =SUM(K30,K32) -> 267771.5 | L33: =SUM(L30,L32) -> 38245.445 | M33: =SUM(M30,M32) -> 39392.808 | N33: =SUM(N30,N32) -> 40574.593 | O33: =SUM(O30,O32) -> 41791.83 | P33: =SUM(P30,P32) -> 638305.59 | ... R33: =SUM(R30,R32) -> 45667.061
B34: Fill in missing formula or reference (no hardcoding) | G34: CF Before Debt Service | I34: =SUM(I26-I33) -> 1948578.7 | J34: =SUM(J26-J33) -> 2007036.1 | K34: =SUM(K26-K33) -> 1836607.1 | L34: =SUM(L26-L33) -> 2129264.6 | M34: =SUM(M26-M33) -> 2193142.5 | N34: =SUM(N26-N33) -> 2258936.8 | O34: =SUM(O26-O33) -> 2326704.9 | P34: =SUM(P26-P33) -> 1801246 | ... R34: =SUM(R26-R33) -> 2542453.2
G36: Unlevered Cash Flow:
G38: Purchase Price | H38: =-C6 -> -38900000
G39: CF Before Debt Service | I39: =I34 -> 1948578.7 | J39: =J34 -> 2007036.1 | K39: =K34 -> 1836607.1 | L39: =L34 -> 2129264.6 | M39: =M34 -> 2193142.5 | N39: =N34 -> 2258936.8 | O39: =O34 -> 2326704.9 | P39: =P34 -> 1801246 | ... R39: =R34 -> 2542453.2
G40: Reversion Proceeds | R40: =C23 -> 39670461
G41: Total Cash Flow | H41: =H38 -> -38900000 | I41: =I39 -> 1948578.7 | J41: =J39 -> 2007036.1 | K41: =K39 -> 1836607.1 | L41: =L39 -> 2129264.6 | M41: =M39 -> 2193142.5 | N41: =N39 -> 2258936.8 | O41: =O39 -> 2326704.9 | P41: =P39 -> 1801246 | Q41: =Q39 -> 2468401.2 | R41: =R39+R40 -> 42212914
G43: Unlevered IRR | H43: =IRR(H41:R41) -> 0.056205811
G45: Loan Amortization: | H45: [COMPLETE LOAN AMORTIZATION TAB]
G47: Beginning Balance | I47: =PV($C$28/12,($C$29-(I2-1))*12,-$C$30) -> 23000000 | J47: =PV($C$28/12,($C$29-(J2-1))*12,-$C$30) -> 22617660 | K47: =PV($C$28/12,($C$29-(K2-1))*12,-$C$30) -> 22218432 | L47: =PV($C$28/12,($C$29-(L2-1))*12,-$C$30) -> 21801570 | M47: =PV($C$28/12,($C$29-(M2-1))*12,-$C$30) -> 21366296 | N47: =PV($C$28/12,($C$29-(N2-1))*12,-$C$30) -> 20911795 | O47: =PV($C$28/12,($C$29-(O2-1))*12,-$C$30) -> 20437220 | P47: =PV($C$28/12,($C$29-(P2-1))*12,-$C$30) -> 19941682 | ... R47: =PV($C$28/12,($C$29-(R2-1))*12,-$C$30) -> 18883977
G48: Loan Payment | I48: =VLOOKUP(I$2,'Loan Amortization_BLANK'!$J$15:$N$44,2,FALSE) -> 1370711.5 | J48: =VLOOKUP(J$2,'Loan Amortization_BLANK'!$J$15:$N$44,2,FALSE) -> 1370711.5 | K48: =VLOOKUP(K$2,'Loan Amortization_BLANK'!$J$15:$N$44,2,FALSE) -> 1370711.5 | L48: =VLOOKUP(L$2,'Loan Amortization_BLANK'!$J$15:$N$44,2,FALSE) -> 1370711.5 | M48: =VLOOKUP(M$2,'Loan Amortization_BLANK'!$J$15:$N$44,2,FALSE) -> 1370711.5 | N48: =VLOOKUP(N$2,'Loan Amortization_BLANK'!$J$15:$N$44,2,FALSE) -> 1370711.5 | O48: =VLOOKUP(O$2,'Loan Amortization_BLANK'!$J$15:$N$44,2,FALSE) -> 1370711.5 | P48: =VLOOKUP(P$2,'Loan Amortization_BLANK'!$J$15:$N$44,2,FALSE) -> 1370711.5 | ... R48: =VLOOKUP(R$2,'Loan Amortization_BLANK'!$J$15:$N$44,2,FALSE) -> 1370711.5
...

Sheet Loan Amortization_BLANK
B2: Loan Information
B3: Loan Amount | D3: 23000000
B4: Rate (Annual) | D4: 0.0433
B5: Term of Loan (Years) | D5: 10
B6: Amortization (Years) | D6: ='Pro Forma_BLANK'!C29 -> 30
B7: Monthly Payment | D7: ='Pro Forma_BLANK'!C30 -> 114225.96
B8: Annual Payment | D8: =D7*12 -> 1370711.5
B11: Monthly Amortization Schedule | J11: Annual Amounts
F12: COMPLETE THESE COLUMNS
B13: Month | C13: Year | D13: BOP Balance | E13: Total Payment | F13: Interest Payment | G13: Principal Payment | H13: EOP Balance | J13: Year | K13: Total Payment | L13: Interest Payment | M13: Principal Payment | N13: EOP Balance
H14: =D3 -> 23000000
B15: 1 | C15: 1 | D15: =H14 -> 23000000 | E15: =$D$7 -> 114225.96 | F15: =D15*($D$4/12) -> 82991.667 | G15: =E15-F15 -> 31234.291 | H15: =D15-G15 -> 22968766 | J15: 1 | K15: =SUMIF($C$15:$C$374,$J15,$E$15:$E$374) -> 1370711.5 | L15: =SUMIF($C$15:$C$374,$J15,$F$15:$F$374) -> 988371.36 | M15: =SUMIF($C$15:$C$374,$J15,$G$15:$G$374) -> 382340.14 | N15: =VLOOKUP(P15,$B$15:$H$374,7,FALSE) -> 22617660 | P15: =J15*12 -> 12
B16: =B15+1 -> 2 | C16: 1 | D16: =H15 -> 22968766 | E16: =$D$7 -> 114225.96 | F16: =D16*($D$4/12) -> 82878.963 | G16: =E16-F16 -> 31346.995 | H16: =D16-G16 -> 22937419 | J16: =J15+1 -> 2 | K16: =SUMIF($C$15:$C$374,$J16,$E$15:$E$374) -> 1370711.5 | L16: =SUMIF($C$15:$C$374,$J16,$F$15:$F$374) -> 971483.49 | M16: =SUMIF($C$15:$C$374,$J16,$G$15:$G$374) -> 399228 | N16: =VLOOKUP(P16,$B$15:$H$374,7,FALSE) -> 22218432 | P16: =J16*12 -> 24
B17: =B16+1 -> 3 | C17: 1 | D17: =H16 -> 22937419 | E17: =$D$7 -> 114225.96 | F17: =D17*($D$4/12) -> 82765.853 | G17: =E17-F17 -> 31460.105 | H17: =D17-G17 -> 22905959 | J17: =J16+1 -> 3 | K17: =SUMIF($C$15:$C$374,$J17,$E$15:$E$374) -> 1370711.5 | L17: =SUMIF($C$15:$C$374,$J17,$F$15:$F$374) -> 953849.69 | M17: =SUMIF($C$15:$C$374,$J17,$G$15:$G$374) -> 416861.8 | N17: =VLOOKUP(P17,$B$15:$H$374,7,FALSE) -> 21801570 | P17: =J17*12 -> 36
B18: =B17+1 -> 4 | C18: 1 | D18: =H17 -> 22905959 | E18: =$D$7 -> 114225.96 | F18: =D18*($D$4/12) -> 82652.334 | G18: =E18-F18 -> 31573.624 | H18: =D18-G18 -> 22874385 | J18: =J17+1 -> 4 | K18: =SUMIF($C$15:$C$374,$J18,$E$15:$E$374) -> 1370711.5 | L18: =SUMIF($C$15:$C$374,$J18,$F$15:$F$374) -> 935437.01 | M18: =SUMIF($C$15:$C$374,$J18,$G$15:$G$374) -> 435274.48 | N18: =VLOOKUP(P18,$B$15:$H$374,7,FALSE) -> 21366296 | P18: =J18*12 -> 48
B19: =B18+1 -> 5 | C19: 1 | D19: =H18 -> 22874385 | E19: =$D$7 -> 114225.96 | F19: =D19*($D$4/12) -> 82538.406 | G19: =E19-F19 -> 31687.552 | H19: =D19-G19 -> 22842697 | J19: =J18+1 -> 5 | K19: =SUMIF($C$15:$C$374,$J19,$E$15:$E$374) -> 1370711.5 | L19: =SUMIF($C$15:$C$374,$J19,$F$15:$F$374) -> 916211.05 | M19: =SUMIF($C$15:$C$374,$J19,$G$15:$G$374) -> 454500.44 | N19: =VLOOKUP(P19,$B$15:$H$374,7,FALSE) -> 20911795 | P19: =J19*12 -> 60
B20: =B19+1 -> 6 | C20: 1 | D20: =H19 -> 22842697 | E20: =$D$7 -> 114225.96 | F20: =D20*($D$4/12) -> 82424.067 | G20: =E20-F20 -> 31801.891 | H20: =D20-G20 -> 22810896 | J20: =J19+1 -> 6 | K20: =SUMIF($C$15:$C$374,$J20,$E$15:$E$374) -> 1370711.5 | L20: =SUMIF($C$15:$C$374,$J20,$F$15:$F$374) -> 896135.88 | M20: =SUMIF($C$15:$C$374,$J20,$G$15:$G$374) -> 474575.61 | N20: =VLOOKUP(P20,$B$15:$H$374,7,FALSE) -> 20437220 | P20: =J20*12 -> 72
B21: =B20+1 -> 7 | C21: 1 | D21: =H20 -> 22810896 | E21: =$D$7 -> 114225.96 | F21: =D21*($D$4/12) -> 82309.315 | G21: =E21-F21 -> 31916.643 | H21: =D21-G21 -> 22778979 | J21: =J20+1 -> 7 | K21: =SUMIF($C$15:$C$374,$J21,$E$15:$E$374) -> 1370711.5 | L21: =SUMIF($C$15:$C$374,$J21,$F$15:$F$374) -> 875174 | M21: =SUMIF($C$15:$C$374,$J21,$G$15:$G$374) -> 495537.5 | N21: =VLOOKUP(P21,$B$15:$H$374,7,FALSE) -> 19941682 | P21: =J21*12 -> 84
B22: =B21+1 -> 8 | C22: 1 | D22: =H21 -> 22778979 | E22: =$D$7 -> 114225.96 | F22: =D22*($D$4/12) -> 82194.149 | G22: =E22-F22 -> 32031.809 | H22: =D22-G22 -> 22746947 | J22: =J21+1 -> 8 | K22: =SUMIF($C$15:$C$374,$J22,$E$15:$E$374) -> 1370711.5 | L22: =SUMIF($C$15:$C$374,$J22,$F$15:$F$374) -> 853286.23 | M22: =SUMIF($C$15:$C$374,$J22,$G$15:$G$374) -> 517425.26 | N22: =VLOOKUP(P22,$B$15:$H$374,7,FALSE) -> 19424257 | P22: =J22*12 -> 96
B23: =B22+1 -> 9 | C23: 1 | D23: =H22 -> 22746947 | E23: =$D$7 -> 114225.96 | F23: =D23*($D$4/12) -> 82078.567 | G23: =E23-F23 -> 32147.39 | H23: =D23-G23 -> 22714800 | J23: =J22+1 -> 9 | K23: =SUMIF($C$15:$C$374,$J23,$E$15:$E$374) -> 1370711.5 | L23: =SUMIF($C$15:$C$374,$J23,$F$15:$F$374) -> 830431.69 | M23: =SUMIF($C$15:$C$374,$J23,$G$15:$G$374) -> 540279.8 | N23: =VLOOKUP(P23,$B$15:$H$374,7,FALSE) -> 18883977 | P23: =J23*12 -> 108
B24: =B23+1 -> 10 | C24: 1 | D24: =H23 -> 22714800 | E24: =$D$7 -> 114225.96 | F24: =D24*($D$4/12) -> 81962.569 | G24: =E24-F24 -> 32263.389 | H24: =D24-G24 -> 22682536 | J24: =J23+1 -> 10 | K24: =SUMIF($C$15:$C$374,$J24,$E$15:$E$374) -> 1370711.5 | L24: =SUMIF($C$15:$C$374,$J24,$F$15:$F$374) -> 806567.67 | M24: =SUMIF($C$15:$C$374,$J24,$G$15:$G$374) -> 564143.82 | N24: =VLOOKUP(P24,$B$15:$H$374,7,FALSE) -> 18319833 | P24: =J24*12 -> 120
B25: =B24+1 -> 11 | C25: 1 | D25: =H24 -> 22682536 | E25: =$D$7 -> 114225.96 | F25: =D25*($D$4/12) -> 81846.152 | G25: =E25-F25 -> 32379.806 | H25: =D25-G25 -> 22650157 | J25: =J24+1 -> 11 | K25: =SUMIF($C$15:$C$374,$J25,$E$15:$E$374) -> 1370711.5 | L25: =SUMIF($C$15:$C$374,$J25,$F$15:$F$374) -> 781649.58 | M25: =SUMIF($C$15:$C$374,$J25,$G$15:$G$374) -> 589061.91 | N25: =VLOOKUP(P25,$B$15:$H$374,7,FALSE) -> 17730771 | P25: =J25*12 -> 132
B26: =B25+1 -> 12 | C26: 1 | D26: =H25 -> 22650157 | E26: =$D$7 -> 114225.96 | F26: =D26*($D$4/12) -> 81729.315 | G26: =E26-F26 -> 32496.643 | H26: =D26-G26 -> 22617660 | J26: =J25+1 -> 12 | K26: =SUMIF($C$15:$C$374,$J26,$E$15:$E$374) -> 1370711.5 | L26: =SUMIF($C$15:$C$374,$J26,$F$15:$F$374) -> 755630.86 | M26: =SUMIF($C$15:$C$374,$J26,$G$15:$G$374) -> 615080.63 | N26: =VLOOKUP(P26,$B$15:$H$374,7,FALSE) -> 17115691 | P26: =J26*12 -> 144
B27: =B26+1 -> 13 | C27: =C15+1 -> 2 | D27: =H26 -> 22617660 | E27: =$D$7 -> 114225.96 | F27: =D27*($D$4/12) -> 81612.056 | G27: =E27-F27 -> 32613.902 | H27: =D27-G27 -> 22585046 | J27: =J26+1 -> 13 | K27: =SUMIF($C$15:$C$374,$J27,$E$15:$E$374) -> 1370711.5 | L27: =SUMIF($C$15:$C$374,$J27,$F$15:$F$374) -> 728462.91 | M27: =SUMIF($C$15:$C$374,$J27,$G$15:$G$374) -> 642248.58 | N27: =VLOOKUP(P27,$B$15:$H$374,7,FALSE) -> 16473442 | P27: =J27*12 -> 156
B28: =B27+1 -> 14 | C28: =C16+1 -> 2 | D28: =H27 -> 22585046 | E28: =$D$7 -> 114225.96 | F28: =D28*($D$4/12) -> 81494.374 | G28: =E28-F28 -> 32731.583 | H28: =D28-G28 -> 22552314 | J28: =J27+1 -> 14 | K28: =SUMIF($C$15:$C$374,$J28,$E$15:$E$374) -> 1370711.5 | L28: =SUMIF($C$15:$C$374,$J28,$F$15:$F$374) -> 700094.95 | M28: =SUMIF($C$15:$C$374,$J28,$G$15:$G$374) -> 670616.54 | N28: =VLOOKUP(P28,$B$15:$H$374,7,FALSE) -> 15802825 | P28: =J28*12 -> 168
B29: =B28+1 -> 15 | C29: =C17+1 -> 2 | D29: =H28 -> 22552314 | E29: =$D$7 -> 114225.96 | F29: =D29*($D$4/12) -> 81376.268 | G29: =E29-F29 -> 32849.69 | H29: =D29-G29 -> 22519465 | J29: =J28+1 -> 15 | K29: =SUMIF($C$15:$C$374,$J29,$E$15:$E$374) -> 1370711.5 | L29: =SUMIF($C$15:$C$374,$J29,$F$15:$F$374) -> 670473.99 | M29: =SUMIF($C$15:$C$374,$J29,$G$15:$G$374) -> 700237.5 | N29: =VLOOKUP(P29,$B$15:$H$374,7,FALSE) -> 15102588 | P29: =J29*12 -> 180
B30: =B29+1 -> 16 | C30: =C18+1 -> 2 | D30: =H29 -> 22519465 | E30: =$D$7 -> 114225.96 | F30: =D30*($D$4/12) -> 81257.735 | G30: =E30-F30 -> 32968.223 | H30: =D30-G30 -> 22486496 | J30: =J29+1 -> 16 | K30: =SUMIF($C$15:$C$374,$J30,$E$15:$E$374) -> 1370711.5 | L30: =SUMIF($C$15:$C$374,$J30,$F$15:$F$374) -> 639544.68 | M30: =SUMIF($C$15:$C$374,$J30,$G$15:$G$374) -> 731166.81 | N30: =VLOOKUP(P30,$B$15:$H$374,7,FALSE) -> 14371421 | P30: =J30*12 -> 192
B31: =B30+1 -> 17 | C31: =C19+1 -> 2 | D31: =H30 -> 22486496 | E31: =$D$7 -> 114225.96 | F31: =D31*($D$4/12) -> 81138.775 | G31: =E31-F31 -> 33087.183 | H31: =D31-G31 -> 22453409 | J31: =J30+1 -> 17 | K31: =SUMIF($C$15:$C$374,$J31,$E$15:$E$374) -> 1370711.5 | L31: =SUMIF($C$15:$C$374,$J31,$F$15:$F$374) -> 607249.23 | M31: =SUMIF($C$15:$C$374,$J31,$G$15:$G$374) -> 763462.26 | N31: =VLOOKUP(P31,$B$15:$H$374,7,FALSE) -> 13607959 | P31: =J31*12 -> 204
B32: =B31+1 -> 18 | C32: =C20+1 -> 2 | D32: =H31 -> 22453409 | E32: =$D$7 -> 114225.96 | F32: =D32*($D$4/12) -> 81019.385 | G32: =E32-F32 -> 33206.572 | H32: =D32-G32 -> 22420203 | J32: =J31+1 -> 18 | K32: =SUMIF($C$15:$C$374,$J32,$E$15:$E$374) -> 1370711.5 | L32: =SUMIF($C$15:$C$374,$J32,$F$15:$F$374) -> 573527.3 | M32: =SUMIF($C$15:$C$374,$J32,$G$15:$G$374) -> 797184.19 | N32: =VLOOKUP(P32,$B$15:$H$374,7,FALSE) -> 12810775 | P32: =J32*12 -> 216
B33: =B32+1 -> 19 | C33: =C21+1 -> 2 | D33: =H32 -> 22420203 | E33: =$D$7 -> 114225.96 | F33: =D33*($D$4/12) -> 80899.565 | G33: =E33-F33 -> 33326.393 | H33: =D33-G33 -> 22386876 | J33: =J32+1 -> 19 | K33: =SUMIF($C$15:$C$374,$J33,$E$15:$E$374) -> 1370711.5 | L33: =SUMIF($C$15:$C$374,$J33,$F$15:$F$374) -> 538315.87 | M33: =SUMIF($C$15:$C$374,$J33,$G$15:$G$374) -> 832395.62 | N33: =VLOOKUP(P33,$B$15:$H$374,7,FALSE) -> 11978379 | P33: =J33*12 -> 228
B34: =B33+1 -> 20 | C34: =C22+1 -> 2 | D34: =H33 -> 22386876 | E34: =$D$7 -> 114225.96 | F34: =D34*($D$4/12) -> 80779.312 | G34: =E34-F34 -> 33446.646 | H34: =D34-G34 -> 22353430 | J34: =J33+1 -> 20 | K34: =SUMIF($C$15:$C$374,$J34,$E$15:$E$374) -> 1370711.5 | L34: =SUMIF($C$15:$C$374,$J34,$F$15:$F$374) -> 501549.17 | M34: =SUMIF($C$15:$C$374,$J34,$G$15:$G$374) -> 869162.32 | N34: =VLOOKUP(P34,$B$15:$H$374,7,FALSE) -> 11109217 | P34: =J34*12 -> 240
B35: =B34+1 -> 21 | C35: =C23+1 -> 2 | D35: =H34 -> 22353430 | E35: =$D$7 -> 114225.96 | F35: =D35*($D$4/12) -> 80658.625 | G35: =E35-F35 -> 33567.332 | H35: =D35-G35 -> 22319862 | J35: =J34+1 -> 21 | K35: =SUMIF($C$15:$C$374,$J35,$E$15:$E$374) -> 1370711.5 | L35: =SUMIF($C$15:$C$374,$J35,$F$15:$F$374) -> 463158.5 | M35: =SUMIF($C$15:$C$374,$J35,$G$15:$G$374) -> 907553 | N35: =VLOOKUP(P35,$B$15:$H$374,7,FALSE) -> 10201664 | P35: =J35*12 -> 252
B36: =B35+1 -> 22 | C36: =C24+1 -> 2 | D36: =H35 -> 22319862 | E36: =$D$7 -> 114225.96 | F36: =D36*($D$4/12) -> 80537.503 | G36: =E36-F36 -> 33688.454 | H36: =D36-G36 -> 22286174 | J36: =J35+1 -> 22 | K36: =SUMIF($C$15:$C$374,$J36,$E$15:$E$374) -> 1370711.5 | L36: =SUMIF($C$15:$C$374,$J36,$F$15:$F$374) -> 423072.11 | M36: =SUMIF($C$15:$C$374,$J36,$G$15:$G$374) -> 947639.38 | N36: =VLOOKUP(P36,$B$15:$H$374,7,FALSE) -> 9254024.4 | P36: =J36*12 -> 264
B37: =B36+1 -> 23 | C37: =C25+1 -> 2 | D37: =H36 -> 22286174 | E37: =$D$7 -> 114225.96 | F37: =D37*($D$4/12) -> 80415.944 | G37: =E37-F37 -> 33810.014 | H37: =D37-G37 -> 22252364 | J37: =J36+1 -> 23 | K37: =SUMIF($C$15:$C$374,$J37,$E$15:$E$374) -> 1370711.5 | L37: =SUMIF($C$15:$C$374,$J37,$F$15:$F$374) -> 381215.12 | M37: =SUMIF($C$15:$C$374,$J37,$G$15:$G$374) -> 989496.37 | N37: =VLOOKUP(P37,$B$15:$H$374,7,FALSE) -> 8264528 | P37: =J37*12 -> 276
B38: =B37+1 -> 24 | C38: =C26+1 -> 2 | D38: =H37 -> 22252364 | E38: =$D$7 -> 114225.96 | F38: =D38*($D$4/12) -> 80293.946 | G38: =E38-F38 -> 33932.011 | H38: =D38-G38 -> 22218432 | J38: =J37+1 -> 24 | K38: =SUMIF($C$15:$C$374,$J38,$E$15:$E$374) -> 1370711.5 | L38: =SUMIF($C$15:$C$374,$J38,$F$15:$F$374) -> 337509.32 | M38: =SUMIF($C$15:$C$374,$J38,$G$15:$G$374) -> 1033202.2 | N38: =VLOOKUP(P38,$B$15:$H$374,7,FALSE) -> 7231325.9 | P38: =J38*12 -> 288
... B44: =B43+1 -> 30 | C44: =C32+1 -> 3 | D44: =H43 -> 22046926 | E44: =$D$7 -> 114225.96 | F44: =D44*($D$4/12) -> 79552.659 | G44: =E44-F44 -> 34673.298 | H44: =D44-G44 -> 22012253 | J44: =J43+1 -> 30 | K44: =SUMIF($C$15:$C$374,$J44,$E$15:$E$374) -> 1370711.5 | L44: =SUMIF($C$15:$C$374,$J44,$F$15:$F$374) -> 31614.786 | M44: =SUMIF($C$15:$C$374,$J44,$G$15:$G$374) -> 1339096.7 | N44: =VLOOKUP(P44,$B$15:$H$374,7,FALSE) -> 9.7774318e-08 | P44: =J44*12 -> 360
B45: =B44+1 -> 31 | C45: =C33+1 -> 3 | D45: =H44 -> 22012253 | E45: =$D$7 -> 114225.96 | F45: =D45*($D$4/12) -> 79427.547 | G45: =E45-F45 -> 34798.411 | H45: =D45-G45 -> 21977455
B46: =B45+1 -> 32 | C46: =C34+1 -> 3 | D46: =H45 -> 21977455 | E46: =$D$7 -> 114225.96 | F46: =D46*($D$4/12) -> 79301.982 | G46: =E46-F46 -> 34923.975 | H46: =D46-G46 -> 21942531
B47: =B46+1 -> 33 | C47: =C35+1 -> 3 | D47: =H46 -> 21942531 | E47: =$D$7 -> 114225.96 | F47: =D47*($D$4/12) -> 79175.965 | G47: =E47-F47 -> 35049.993 | H47: =D47-G47 -> 21907481
B48: =B47+1 -> 34 | C48: =C36+1 -> 3 | D48: =H47 -> 21907481 | E48: =$D$7 -> 114225.96 | F48: =D48*($D$4/12) -> 79049.493 | G48: =E48-F48 -> 35176.465 | H48: =D48-G48 -> 21872304
...
